<?xml version="1.0" encoding="utf-8"?>
<!-- =================================================================================== -->
<!-- |    This document was autogenerated by xacro from arm_urdf.xacro                 | -->
<!-- |    EDITING THIS FILE BY HAND IS NOT RECOMMENDED                                 | -->
<!-- =================================================================================== -->
<robot name="test_robot">
  <link name="base"/>
  <link name="upperarm">
    <visual>
      <geometry>
        <box size="0.1 0.1 1"/>
      </geometry>
      <origin rpy="0 0 0" xyz="0 0 0.5"/>
      <material name="white">
        <color rgba="1 1 1 1"/>
      </material>
    </visual>
    <collision>
      <geometry>
        <box size="0.1 0.1 1"/>
      </geometry>
      <origin rpy="0 0 0" xyz="0 0 0.5"/>
    </collision>
    <inertial>
      <mass value="1.6"/>
      <origin rpy="0 0 0" xyz="0 0 0"/>
      <inertia ixx="0.006051" ixy="0" ixz="0" iyy="0" iyz="0" izz="0.009098"/>
    </inertial>
  </link>
  <joint name="base_joint" type="fixed">
    <origin rpy="0 0 0" xyz="0 0 0"/>
    <parent link="base"/>
    <child link="upperarm"/>
  </joint>
  <link name="lowerarm">
    <visual>
      <geometry>
        <box size="0.1 0.1 1"/>
      </geometry>
      <origin rpy="0 0 0" xyz="0 0 0.5"/>
      <material name="gray">
        <color rgba="0.8 0.8 0.8 0.5"/>
      </material>
    </visual>
    <collision>
      <geometry>
        <box size="0.1 0.1 1"/>
      </geometry>
      <origin rpy="0 0 0" xyz="0 0 0.05"/>
    </collision>
    <inertial>
      <mass value="1.6"/>
      <origin rpy="0 0 0" xyz="0 0 0"/>
      <inertia ixx="0.006051" ixy="0" ixz="0" iyy="0" iyz="0" izz="0.009098"/>
    </inertial>
  </link>
  <joint name="y_joint" type="continuous">
    <origin rpy="0 0 0" xyz="0.01 0.01 0.95"/>
    <axis xyz="0 1 0"/>
    <parent link="upperarm"/>
    <child link="lowerarm"/>
  </joint>
</robot>

