<robot name="test_robot" xmlns:xacro="http://ros.org/wiki/xacro">
        <link name="base"/>
        <link name="upperarm">
          <visual>
            <geometry>
              <box size="0.1 0.1 1" />
            </geometry>
            <origin xyz="0 0 0.5" rpy="0 0 0"/>
            <material name="white">
              <color rgba="1 1 1 1"/>
            </material>
          </visual>
          <collision>
            <geometry>
                <box size="0.1 0.1 1" />
            </geometry>
            <origin xyz="0 0 0.5" rpy="0 0 0"/>
          </collision>
          <inertial>
            <mass value="1.6"/>
            <origin xyz="0 0 0" rpy="0 0 0"/>
            <inertia ixx="0.006051" iyy="0" izz="0.009098" ixy="0" ixz="0" iyz="0"/>
          </inertial>
        </link>

        <joint name="base_joint" type="fixed">
            <origin xyz="0 0 0" rpy="0 0 0"/>
            <parent link="base"/>
            <child link="upperarm" />
        </joint>

        <link name="lowerarm">
          <visual>
            <geometry>
              <box size="0.1 0.1 1" />
            </geometry>
            <origin xyz="0 0 0.5" rpy="0 0 0"/>
            <material name="gray">
                <color rgba="0.8 0.8 0.8 0.5"/>
            </material>
          </visual>
          <collision>
            <geometry>
                <box size="0.1 0.1 1" />
            </geometry>
            <origin xyz="0 0 0.05" rpy="0 0 0"/>
          </collision>
          <inertial>
            <mass value="1.6"/>
            <origin xyz="0 0 0" rpy="0 0 0"/>
            <inertia ixx="0.006051" iyy="0" izz="0.009098" ixy="0" ixz="0" iyz="0"/>
          </inertial>
        </link>

        <joint name="y_joint" type="continuous">
            <origin xyz="0.01 0.01 0.95" rpy="0 0 0"/>
            <axis xyz="0 1 0"/>
            <parent link="upperarm"/>
            <child link="lowerarm"/>
        </joint>
</robot>